File: EC4/CF1.csv
Test Name,Test Mode,Test Type,Control,Test Speed 1,Test Speed 2,Test Speed 3,Change Point 1,Change Point 2,Disp. Origin,Break and Limit Action,Sensitivity:,Level:
,Single,Tensile,Stroke,10,1,1,Off,Off,Start,Stop,50,5
,,,,,,,,,,,,
Title,Sub title,Comment,,,,,,,,,,
,,,,,,,,,,,,
,,,,,,,,,,,,
Shape:,Batch Size:,SubBatch Size:,,,,,,,,,,
Plate,1,1,,,,,,,,,,
Name:,Thickness,Width,Gauge Length,,,,,,,,,
Size Unit:,mm,mm,mm,,,,,,,,,
 Carbon Fiber,1.61,11.22,60,,,,,,,,,
,,,,,,,,,,,,
Name,Max_Force,,,,,,,,,,,
Parameter,,,,,,,,,,,,
Units,kN,,,,,,,,,,,
 Carbon Fiber,6.26906,,,,,,,,,,,
,,,,,,,,,,,,
 1- 1,,,,,,,,,,,,
Time,Force,Stroke,,,,,,,,,,
sec,kN,mm,,,,,,,,,,
0,-0.0003125,0,,,,,,,,,,
0.05,-0.000625,0,,,,,,,,,,
0.1,0.0009375,0.004,,,,,,,,,,
0.15,0.0084375,0.012,,,,,,,,,,
0.2,0.0234375,0.02,,,,,,,,,,
0.25,0.0415625,0.028,,,,,,,,,,
0.3,0.0575,0.036,,,,,,,,,,
0.35,0.0721875,0.045,,,,,,,,,,
0.4,0.0853125,0.053,,,,,,,,,,
0.45,0.09875,0.061,,,,,,,,,,
0.5,0.1125,0.07,,,,,,,,,,
0.55,0.1259375,0.078,,,,,,,,,,
0.6,0.14125,0.086,,,,,,,,,,
0.65,0.158125,0.095,,,,,,,,,,
0.7,0.1740625,0.103,,,,,,,,,,
0.75,0.191875,0.111,,,,,,,,,,
0.8,0.21125,0.12,,,,,,,,,,
0.85,0.230625,0.128,,,,,,,,,,
0.9,0.250625,0.136,,,,,,,,,,
0.95,0.2721875,0.145,,,,,,,,,,
1,0.295,0.153,,,,,,,,,,
1.05,0.3165625,0.161,,,,,,,,,,
1.1,0.3375,0.17,,,,,,,,,,
1.15,0.36,0.178,,,,,,,,,,
1.2,0.3840625,0.186,,,,,,,,,,
1.25,0.4090625,0.195,,,,,,,,,,
1.3,0.43375,0.203,,,,,,,,,,
1.35,0.4584375,0.211,,,,,,,,,,
1.4,0.483125,0.22,,,,,,,,,,
1.45,0.5084375,0.228,,,,,,,,,,
1.5,0.531875,0.236,,,,,,,,,,
1.55,0.5559375,0.245,,,,,,,,,,
1.6,0.58,0.253,,,,,,,,,,
1.65,0.6021875,0.261,,,,,,,,,,
1.7,0.625,0.27,,,,,,,,,,
1.75,0.645,0.278,,,,,,,,,,
1.8,0.6653125,0.286,,,,,,,,,,
1.85,0.68375,0.295,,,,,,,,,,
1.9,0.7009375,0.303,,,,,,,,,,
1.95,0.7184375,0.311,,,,,,,,,,
2,0.7321875,0.32,,,,,,,,,,
2.05,0.7459375,0.328,,,,,,,,,,
2.1,0.758125,0.336,,,,,,,,,,
2.15,0.76875,0.345,,,,,,,,,,
2.2,0.7778125,0.353,,,,,,,,,,
2.25,0.7846875,0.361,,,,,,,,,,
2.3,0.7928125,0.37,,,,,,,,,,
2.35,0.79875,0.378,,,,,,,,,,
2.4,0.806875,0.386,,,,,,,,,,
2.45,0.8146875,0.395,,,,,,,,,,
2.5,0.8221875,0.403,,,,,,,,,,
2.55,0.83125,0.411,,,,,,,,,,
2.6,0.840625,0.42,,,,,,,,,,
2.65,0.8496875,0.428,,,,,,,,,,
2.7,0.85875,0.436,,,,,,,,,,
2.75,0.8684375,0.445,,,,,,,,,,
2.8,0.8784375,0.453,,,,,,,,,,
2.85,0.8890625,0.461,,,,,,,,,,
2.9,0.8984375,0.47,,,,,,,,,,
2.95,0.9096875,0.478,,,,,,,,,,
3,0.9203125,0.486,,,,,,,,,,
3.05,0.93125,0.495,,,,,,,,,,
3.1,0.9421875,0.503,,,,,,,,,,
3.15,0.9525,0.511,,,,,,,,,,
3.2,0.963125,0.52,,,,,,,,,,
3.25,0.9759375,0.528,,,,,,,,,,
3.3,0.985,0.536,,,,,,,,,,
3.35,0.99625,0.545,,,,,,,,,,
3.4,1.006875,0.553,,,,,,,,,,
3.45,1.017812,0.561,,,,,,,,,,
3.5,1.028437,0.57,,,,,,,,,,
3.55,1.039063,0.578,,,,,,,,,,
3.6,1.05,0.586,,,,,,,,,,
3.65,1.061563,0.595,,,,,,,,,,
3.7,1.07125,0.603,,,,,,,,,,
3.75,1.081563,0.611,,,,,,,,,,
3.8,1.092188,0.62,,,,,,,,,,
3.85,1.103438,0.628,,,,,,,,,,
3.9,1.114687,0.636,,,,,,,,,,
3.95,1.125937,0.645,,,,,,,,,,
4,1.136875,0.653,,,,,,,,,,
4.05,1.147812,0.661,,,,,,,,,,
4.1,1.159063,0.67,,,,,,,,,,
4.15,1.170313,0.678,,,,,,,,,,
4.2,1.182188,0.686,,,,,,,,,,
4.25,1.19375,0.695,,,,,,,,,,
4.3,1.205625,0.703,,,,,,,,,,
4.35,1.215625,0.711,,,,,,,,,,
4.4,1.2275,0.72,,,,,,,,,,
4.45,1.239687,0.728,,,,,,,,,,
4.5,1.249375,0.736,,,,,,,,,,
4.55,1.260313,0.745,,,,,,,,,,
4.6,1.271562,0.753,,,,,,,,,,
4.65,1.282187,0.761,,,,,,,,,,
4.7,1.293125,0.77,,,,,,,,,,
4.75,1.304375,0.778,,,,,,,,,,
4.8,1.315313,0.786,,,,,,,,,,
4.85,1.326563,0.795,,,,,,,,,,
4.9,1.336563,0.803,,,,,,,,,,
4.95,1.347188,0.811,,,,,,,,,,
5,1.359063,0.82,,,,,,,,,,
5.05,1.368125,0.828,,,,,,,,,,
5.1,1.378438,0.836,,,,,,,,,,
5.15,1.38875,0.845,,,,,,,,,,
5.2,1.399063,0.853,,,,,,,,,,
5.25,1.409063,0.861,,,,,,,,,,
5.3,1.41875,0.87,,,,,,,,,,
5.35,1.429375,0.878,,,,,,,,,,
5.4,1.438437,0.886,,,,,,,,,,
5.45,1.447188,0.895,,,,,,,,,,
5.5,1.455938,0.903,,,,,,,,,,
5.55,1.464062,0.911,,,,,,,,,,
5.6,1.473125,0.92,,,,,,,,,,
5.65,1.48125,0.928,,,,,,,,,,
5.7,1.490625,0.936,,,,,,,,,,
5.75,1.5,0.945,,,,,,,,,,
5.8,1.509063,0.953,,,,,,,,,,
5.85,1.5175,0.961,,,,,,,,,,
5.9,1.525313,0.97,,,,,,,,,,
5.95,1.531875,0.978,,,,,,,,,,
6,1.539375,0.986,,,,,,,,,,
6.05,1.545625,0.995,,,,,,,,,,
6.1,1.555313,1.003,,,,,,,,,,
6.15,1.5625,1.011,,,,,,,,,,
6.2,1.57,1.02,,,,,,,,,,
6.25,1.579375,1.028,,,,,,,,,,
6.3,1.587188,1.036,,,,,,,,,,
6.35,1.595,1.045,,,,,,,,,,
6.4,1.604063,1.053,,,,,,,,,,
6.45,1.613125,1.061,,,,,,,,,,
6.5,1.62375,1.07,,,,,,,,,,
6.55,1.630937,1.078,,,,,,,,,,
6.6,1.639688,1.086,,,,,,,,,,
6.65,1.649063,1.095,,,,,,,,,,
6.7,1.657187,1.103,,,,,,,,,,
6.75,1.666563,1.111,,,,,,,,,,
6.8,1.675625,1.12,,,,,,,,,,
6.85,1.68375,1.128,,,,,,,,,,
6.9,1.693437,1.136,,,,,,,,,,
6.95,1.7025,1.145,,,,,,,,,,
7,1.710625,1.153,,,,,,,,,,
7.05,1.719687,1.161,,,,,,,,,,
7.1,1.728438,1.17,,,,,,,,,,
7.15,1.7375,1.178,,,,,,,,,,
7.2,1.746875,1.186,,,,,,,,,,
7.25,1.755,1.195,,,,,,,,,,
7.3,1.76375,1.203,,,,,,,,,,
7.35,1.772812,1.211,,,,,,,,,,
7.4,1.782187,1.22,,,,,,,,,,
7.45,1.79125,1.228,,,,,,,,,,
7.5,1.799375,1.236,,,,,,,,,,
7.55,1.80875,1.245,,,,,,,,,,
7.6,1.817812,1.253,,,,,,,,,,
7.65,1.827188,1.261,,,,,,,,,,
7.7,1.83625,1.27,,,,,,,,,,
7.75,1.845312,1.278,,,,,,,,,,
7.8,1.855625,1.286,,,,,,,,,,
7.85,1.863125,1.295,,,,,,,,,,
7.9,1.872813,1.303,,,,,,,,,,
7.95,1.88125,1.311,,,,,,,,,,
8,1.89,1.32,,,,,,,,,,
8.05,1.899063,1.328,,,,,,,,,,
8.1,1.908125,1.336,,,,,,,,,,
8.15,1.916875,1.345,,,,,,,,,,
8.2,1.9275,1.353,,,,,,,,,,
8.25,1.935625,1.361,,,,,,,,,,
8.3,1.94375,1.37,,,,,,,,,,
8.35,1.952813,1.378,,,,,,,,,,
8.4,1.962188,1.386,,,,,,,,,,
8.45,1.971563,1.395,,,,,,,,,,
8.5,1.980312,1.403,,,,,,,,,,
8.55,1.98875,1.411,,,,,,,,,,
8.6,1.998438,1.42,,,,,,,,,,
8.65,2.0075,1.428,,,,,,,,,,
8.7,2.016875,1.437,,,,,,,,,,
8.75,2.025312,1.445,,,,,,,,,,
8.8,2.034688,1.453,,,,,,,,,,
8.85,2.04375,1.461,,,,,,,,,,
8.9,2.0525,1.47,,,,,,,,,,
8.95,2.061563,1.478,,,,,,,,,,
9,2.07125,1.486,,,,,,,,,,
9.05,2.08,1.495,,,,,,,,,,
9.1,2.089375,1.503,,,,,,,,,,
9.15,2.099375,1.511,,,,,,,,,,
9.2,2.109688,1.52,,,,,,,,,,
9.25,2.11875,1.528,,,,,,,,,,
9.3,2.128125,1.536,,,,,,,,,,
9.35,2.137187,1.545,,,,,,,,,,
9.4,2.146563,1.553,,,,,,,,,,
9.45,2.15625,1.561,,,,,,,,,,
9.5,2.166563,1.57,,,,,,,,,,
9.55,2.175625,1.578,,,,,,,,,,
9.6,2.185313,1.586,,,,,,,,,,
9.65,2.196563,1.595,,,,,,,,,,
9.7,2.206563,1.603,,,,,,,,,,
9.75,2.215938,1.611,,,,,,,,,,
9.8,2.225625,1.62,,,,,,,,,,
9.85,2.235312,1.628,,,,,,,,,,
9.9,2.245,1.636,,,,,,,,,,
9.95,2.254062,1.645,,,,,,,,,,
10,2.263438,1.653,,,,,,,,,,
10.05,2.273438,1.661,,,,,,,,,,
10.1,2.2825,1.67,,,,,,,,,,
10.15,2.2925,1.678,,,,,,,,,,
10.2,2.301875,1.687,,,,,,,,,,
10.25,2.311875,1.695,,,,,,,,,,
10.3,2.321875,1.703,,,,,,,,,,
10.35,2.33125,1.711,,,,,,,,,,
10.4,2.342187,1.72,,,,,,,,,,
10.45,2.35125,1.728,,,,,,,,,,
10.5,2.362187,1.736,,,,,,,,,,
10.55,2.371562,1.745,,,,,,,,,,
10.6,2.381875,1.753,,,,,,,,,,
10.65,2.391875,1.761,,,,,,,,,,
10.7,2.401562,1.77,,,,,,,,,,
10.75,2.411562,1.778,,,,,,,,,,
10.8,2.42125,1.786,,,,,,,,,,
10.85,2.431875,1.795,,,,,,,,,,
10.9,2.444062,1.803,,,,,,,,,,
10.95,2.4525,1.811,,,,,,,,,,
11,2.463125,1.82,,,,,,,,,,
11.05,2.473125,1.828,,,,,,,,,,
11.1,2.482812,1.836,,,,,,,,,,
11.15,2.493125,1.845,,,,,,,,,,
11.2,2.503125,1.853,,,,,,,,,,
11.25,2.51375,1.861,,,,,,,,,,
11.3,2.524688,1.87,,,,,,,,,,
11.35,2.533437,1.878,,,,,,,,,,
11.4,2.54375,1.886,,,,,,,,,,
11.45,2.55375,1.895,,,,,,,,,,
11.5,2.564063,1.903,,,,,,,,,,
11.55,2.57375,1.911,,,,,,,,,,
11.6,2.58375,1.92,,,,,,,,,,
11.65,2.595,1.928,,,,,,,,,,
11.7,2.604063,1.936,,,,,,,,,,
11.75,2.615,1.945,,,,,,,,,,
11.8,2.625625,1.953,,,,,,,,,,
11.85,2.635313,1.961,,,,,,,,,,
11.9,2.646563,1.97,,,,,,,,,,
11.95,2.656563,1.978,,,,,,,,,,
12,2.667187,1.986,,,,,,,,,,
12.05,2.676563,1.995,,,,,,,,,,
12.1,2.688125,2.003,,,,,,,,,,
12.15,2.698437,2.011,,,,,,,,,,
12.2,2.70875,2.02,,,,,,,,,,
12.25,2.72,2.028,,,,,,,,,,
12.3,2.730625,2.036,,,,,,,,,,
12.35,2.74125,2.045,,,,,,,,,,
12.4,2.7525,2.053,,,,,,,,,,
12.45,2.762813,2.061,,,,,,,,,,
12.5,2.773125,2.07,,,,,,,,,,
12.55,2.784375,2.078,,,,,,,,,,
12.6,2.795312,2.086,,,,,,,,,,
12.65,2.806562,2.095,,,,,,,,,,
12.7,2.8175,2.103,,,,,,,,,,
12.75,2.828125,2.111,,,,,,,,,,
12.8,2.839062,2.12,,,,,,,,,,
12.85,2.849688,2.128,,,,,,,,,,
12.9,2.860938,2.136,,,,,,,,,,
12.95,2.871562,2.145,,,,,,,,,,
13,2.882813,2.153,,,,,,,,,,
13.05,2.893437,2.161,,,,,,,,,,
13.1,2.905313,2.17,,,,,,,,,,
13.15,2.91625,2.178,,,,,,,,,,
13.2,2.925937,2.186,,,,,,,,,,
13.25,2.936875,2.195,,,,,,,,,,
13.3,2.94875,2.203,,,,,,,,,,
13.35,2.959375,2.211,,,,,,,,,,
13.4,2.970625,2.22,,,,,,,,,,
13.45,2.980937,2.228,,,,,,,,,,
13.5,2.992812,2.236,,,,,,,,,,
13.55,3.005,2.245,,,,,,,,,,
13.6,3.016562,2.253,,,,,,,,,,
13.65,3.0275,2.261,,,,,,,,,,
13.7,3.038438,2.27,,,,,,,,,,
13.75,3.050937,2.278,,,,,,,,,,
13.8,3.062187,2.286,,,,,,,,,,
13.85,3.074375,2.295,,,,,,,,,,
13.9,3.086562,2.303,,,,,,,,,,
13.95,3.098438,2.311,,,,,,,,,,
14,3.110312,2.32,,,,,,,,,,
14.05,3.122813,2.328,,,,,,,,,,
14.1,3.133437,2.336,,,,,,,,,,
14.15,3.145,2.345,,,,,,,,,,
14.2,3.158437,2.353,,,,,,,,,,
14.25,3.168437,2.361,,,,,,,,,,
14.3,3.180938,2.37,,,,,,,,,,
14.35,3.192812,2.378,,,,,,,,,,
14.4,3.20375,2.386,,,,,,,,,,
14.45,3.216875,2.395,,,,,,,,,,
14.5,3.2275,2.403,,,,,,,,,,
14.55,3.23875,2.411,,,,,,,,,,
14.6,3.25125,2.42,,,,,,,,,,
14.65,3.263125,2.428,,,,,,,,,,
14.7,3.27375,2.436,,,,,,,,,,
14.75,3.285,2.445,,,,,,,,,,
14.8,3.296875,2.453,,,,,,,,,,
14.85,3.309062,2.461,,,,,,,,,,
14.9,3.320625,2.47,,,,,,,,,,
14.95,3.333437,2.478,,,,,,,,,,
15,3.344687,2.486,,,,,,,,,,
15.05,3.3575,2.495,,,,,,,,,,
15.1,3.370312,2.503,,,,,,,,,,
15.15,3.381875,2.511,,,,,,,,,,
15.2,3.395,2.52,,,,,,,,,,
15.25,3.4075,2.528,,,,,,,,,,
15.3,3.419063,2.536,,,,,,,,,,
15.35,3.432188,2.545,,,,,,,,,,
15.4,3.443438,2.553,,,,,,,,,,
15.45,3.455625,2.561,,,,,,,,,,
15.5,3.46875,2.57,,,,,,,,,,
15.55,3.48,2.578,,,,,,,,,,
15.6,3.493438,2.586,,,,,,,,,,
15.65,3.505,2.595,,,,,,,,,,
15.7,3.516875,2.603,,,,,,,,,,
15.75,3.53,2.611,,,,,,,,,,
15.8,3.5425,2.62,,,,,,,,,,
15.85,3.554688,2.628,,,,,,,,,,
15.9,3.568125,2.636,,,,,,,,,,
15.95,3.580937,2.645,,,,,,,,,,
16,3.592813,2.653,,,,,,,,,,
16.05,3.605,2.661,,,,,,,,,,
16.1,3.618438,2.67,,,,,,,,,,
16.15,3.63,2.678,,,,,,,,,,
16.2,3.643125,2.687,,,,,,,,,,
16.25,3.656875,2.695,,,,,,,,,,
16.3,3.66875,2.703,,,,,,,,,,
16.35,3.681875,2.712,,,,,,,,,,
16.4,3.694688,2.72,,,,,,,,,,
16.45,3.706563,2.728,,,,,,,,,,
16.5,3.719687,2.736,,,,,,,,,,
16.55,3.7325,2.745,,,,,,,,,,
16.6,3.745,2.753,,,,,,,,,,
16.65,3.759375,2.761,,,,,,,,,,
16.7,3.771563,2.77,,,,,,,,,,
16.75,3.785312,2.778,,,,,,,,,,
16.8,3.798125,2.786,,,,,,,,,,
16.85,3.811875,2.795,,,,,,,,,,
16.9,3.823437,2.803,,,,,,,,,,
16.95,3.836875,2.811,,,,,,,,,,
17,3.85,2.82,,,,,,,,,,
17.05,3.863125,2.828,,,,,,,,,,
17.1,3.876563,2.836,,,,,,,,,,
17.15,3.889062,2.845,,,,,,,,,,
17.2,3.902188,2.853,,,,,,,,,,
17.25,3.915625,2.861,,,,,,,,,,
17.3,3.928125,2.87,,,,,,,,,,
17.35,3.94125,2.878,,,,,,,,,,
17.4,3.95375,2.886,,,,,,,,,,
17.45,3.966563,2.895,,,,,,,,,,
17.5,3.979375,2.903,,,,,,,,,,
17.55,3.9925,2.911,,,,,,,,,,
17.6,4.005938,2.92,,,,,,,,,,
17.65,4.018437,2.928,,,,,,,,,,
17.7,4.031562,2.936,,,,,,,,,,
17.75,4.044687,2.945,,,,,,,,,,
17.8,4.057813,2.953,,,,,,,,,,
17.85,4.071562,2.961,,,,,,,,,,
17.9,4.0875,2.97,,,,,,,,,,
17.95,4.098437,2.978,,,,,,,,,,
18,4.113125,2.986,,,,,,,,,,
18.05,4.125625,2.995,,,,,,,,,,
18.1,4.14,3.003,,,,,,,,,,
18.15,4.153438,3.011,,,,,,,,,,
18.2,4.16625,3.02,,,,,,,,,,
18.25,4.18,3.028,,,,,,,,,,
18.3,4.194375,3.036,,,,,,,,,,
18.35,4.207188,3.045,,,,,,,,,,
18.4,4.220938,3.053,,,,,,,,,,
18.45,4.23375,3.061,,,,,,,,,,
18.5,4.249063,3.07,,,,,,,,,,
18.55,4.261875,3.078,,,,,,,,,,
18.6,4.274375,3.086,,,,,,,,,,
18.65,4.288437,3.095,,,,,,,,,,
18.7,4.3025,3.103,,,,,,,,,,
18.75,4.315312,3.111,,,,,,,,,,
18.8,4.329688,3.12,,,,,,,,,,
18.85,4.343125,3.128,,,,,,,,,,
18.9,4.3575,3.136,,,,,,,,,,
18.95,4.37,3.145,,,,,,,,,,
19,4.384687,3.153,,,,,,,,,,
19.05,4.397188,3.161,,,,,,,,,,
19.1,4.41125,3.17,,,,,,,,,,
19.15,4.425,3.178,,,,,,,,,,
19.2,4.437812,3.187,,,,,,,,,,
19.25,4.451875,3.195,,,,,,,,,,
19.3,4.464063,3.203,,,,,,,,,,
19.35,4.47625,3.212,,,,,,,,,,
19.4,4.49,3.22,,,,,,,,,,
19.45,4.50375,3.228,,,,,,,,,,
19.5,4.51625,3.236,,,,,,,,,,
19.55,4.53,3.245,,,,,,,,,,
19.6,4.543125,3.253,,,,,,,,,,
19.65,4.556875,3.261,,,,,,,,,,
19.7,4.569687,3.27,,,,,,,,,,
19.75,4.584063,3.278,,,,,,,,,,
19.8,4.5975,3.286,,,,,,,,,,
19.85,4.61125,3.295,,,,,,,,,,
19.9,4.624688,3.303,,,,,,,,,,
19.95,4.63875,3.311,,,,,,,,,,
20,4.652812,3.32,,,,,,,,,,
20.05,4.6675,3.328,,,,,,,,,,
20.1,4.68125,3.336,,,,,,,,,,
20.15,4.694375,3.345,,,,,,,,,,
20.2,4.709688,3.353,,,,,,,,,,
20.25,4.722188,3.361,,,,,,,,,,
20.3,4.737813,3.37,,,,,,,,,,
20.35,4.751563,3.378,,,,,,,,,,
20.4,4.764688,3.386,,,,,,,,,,
20.45,4.779375,3.395,,,,,,,,,,
20.5,4.791875,3.403,,,,,,,,,,
20.55,4.80625,3.411,,,,,,,,,,
20.6,4.820313,3.42,,,,,,,,,,
20.65,4.834063,3.428,,,,,,,,,,
20.7,4.848125,3.436,,,,,,,,,,
20.75,4.862813,3.445,,,,,,,,,,
20.8,4.876563,3.453,,,,,,,,,,
20.85,4.89,3.461,,,,,,,,,,
20.9,4.905938,3.47,,,,,,,,,,
20.95,4.921875,3.478,,,,,,,,,,
21,4.933125,3.486,,,,,,,,,,
21.05,4.948438,3.495,,,,,,,,,,
21.1,4.964375,3.503,,,,,,,,,,
21.15,4.978125,3.511,,,,,,,,,,
21.2,4.992813,3.52,,,,,,,,,,
21.25,5.007813,3.528,,,,,,,,,,
21.3,5.022188,3.536,,,,,,,,,,
21.35,5.03625,3.545,,,,,,,,,,
21.4,5.05,3.553,,,,,,,,,,
21.45,5.064688,3.561,,,,,,,,,,
21.5,5.079375,3.57,,,,,,,,,,
21.55,5.093125,3.578,,,,,,,,,,
21.6,5.109063,3.587,,,,,,,,,,
21.65,5.124063,3.595,,,,,,,,,,
21.7,5.138437,3.603,,,,,,,,,,
21.75,5.152812,3.611,,,,,,,,,,
21.8,5.167812,3.62,,,,,,,,,,
21.85,5.18375,3.628,,,,,,,,,,
21.9,5.196875,3.636,,,,,,,,,,
21.95,5.212187,3.645,,,,,,,,,,
22,5.225625,3.653,,,,,,,,,,
22.05,5.240313,3.661,,,,,,,,,,
22.1,5.255625,3.67,,,,,,,,,,
22.15,5.270625,3.678,,,,,,,,,,
22.2,5.287188,3.687,,,,,,,,,,
22.25,5.300625,3.695,,,,,,,,,,
22.3,5.315312,3.703,,,,,,,,,,
22.35,5.33,3.712,,,,,,,,,,
22.4,5.344687,3.72,,,,,,,,,,
22.45,5.36,3.728,,,,,,,,,,
22.5,5.374688,3.736,,,,,,,,,,
22.55,5.38875,3.745,,,,,,,,,,
22.6,5.404687,3.753,,,,,,,,,,
22.65,5.419063,3.761,,,,,,,,,,
22.7,5.434375,3.77,,,,,,,,,,
22.75,5.44875,3.778,,,,,,,,,,
22.8,5.463125,3.786,,,,,,,,,,
22.85,5.478125,3.795,,,,,,,,,,
22.9,5.492813,3.803,,,,,,,,,,
22.95,5.507187,3.811,,,,,,,,,,
23,5.523438,3.82,,,,,,,,,,
23.05,5.537813,3.828,,,,,,,,,,
23.1,5.553125,3.836,,,,,,,,,,
23.15,5.568125,3.845,,,,,,,,,,
23.2,5.5825,3.853,,,,,,,,,,
23.25,5.599375,3.861,,,,,,,,,,
23.3,5.613125,3.87,,,,,,,,,,
23.35,5.628438,3.878,,,,,,,,,,
23.4,5.643125,3.886,,,,,,,,,,
23.45,5.658125,3.895,,,,,,,,,,
23.5,5.672812,3.903,,,,,,,,,,
23.55,5.687188,3.911,,,,,,,,,,
23.6,5.701875,3.92,,,,,,,,,,
23.65,5.717187,3.928,,,,,,,,,,
23.7,5.731563,3.936,,,,,,,,,,
23.75,5.747188,3.945,,,,,,,,,,
23.8,5.762187,3.953,,,,,,,,,,
23.85,5.776875,3.961,,,,,,,,,,
23.9,5.793125,3.97,,,,,,,,,,
23.95,5.807813,3.978,,,,,,,,,,
24,5.823438,3.986,,,,,,,,,,
24.05,5.839375,3.995,,,,,,,,,,
24.1,5.855312,4.003,,,,,,,,,,
24.15,5.87,4.011,,,,,,,,,,
24.2,5.885938,4.02,,,,,,,,,,
24.25,5.900625,4.028,,,,,,,,,,
24.3,5.915937,4.036,,,,,,,,,,
24.35,5.93125,4.045,,,,,,,,,,
24.4,5.947187,4.053,,,,,,,,,,
24.45,5.9625,4.061,,,,,,,,,,
24.5,5.97875,4.07,,,,,,,,,,
24.55,5.995313,4.078,,,,,,,,,,
24.6,6.01,4.087,,,,,,,,,,
24.65,6.026563,4.095,,,,,,,,,,
24.7,6.040937,4.103,,,,,,,,,,
24.75,6.055,4.111,,,,,,,,,,
24.8,6.071562,4.12,,,,,,,,,,
24.85,6.087812,4.128,,,,,,,,,,
24.9,6.103125,4.136,,,,,,,,,,
24.95,6.118125,4.145,,,,,,,,,,
25,6.13375,4.153,,,,,,,,,,
25.05,6.15,4.161,,,,,,,,,,
25.1,6.165625,4.17,,,,,,,,,,
25.15,6.181875,4.178,,,,,,,,,,
25.2,6.1975,4.187,,,,,,,,,,
25.25,6.212187,4.195,,,,,,,,,,
25.3,6.227188,4.203,,,,,,,,,,
25.35,6.242188,4.212,,,,,,,,,,
25.4,6.256875,4.22,,,,,,,,,,
25.45,6.269063,4.228,,,,,,,,,,
25.45,6.269063,4.228,,,,,,,,,,
25.45,6.269063,4.228,,,,,,,,,,