File: EC4/CF4.csv
"Test Name","Test Mode","Test Type","Control","Test Speed 1","Test Speed 2","Test Speed 3","Change Point 1","Change Point 2","Disp. Origin","Break and Limit Action","Sensitivity:","Level:"
"","Single","Tensile","Stroke",10,1,1,"Off","Off","Start","Stop",50,5

"Title","Sub title","Comment"
"","",""

"Shape:","Batch Size:","SubBatch Size:"
"Plate",1,1
"Name:","Thickness","Width","Gauge Length",
"Size Unit:","mm","mm","mm",
" Carbon Fiber","1.6500","11.1450","60.0000",

"Name","Max_Force",
"Parameter",,
"Units","kN",
" Carbon Fiber","6.80000",

" 1- 1"
"Time","Force","Stroke",
"sec","kN","mm",
"0.00",0,0,
"0.05",-.0003125,.002,
"0.10",.00125,.01,
"0.15",.00875,.018,
"0.20",.023125,.026,
"0.25",.0396875,.034,
"0.30",.0559375,.042,
"0.35",.0696875,.051,
"0.40",.0809375,.059,
"0.45",.0925,.067,
"0.50",.1028125,.076,
"0.55",.1159375,.084,
"0.60",.128125,.092,
"0.65",.14125,.101,
"0.70",.1540625,.109,
"0.75",.1678125,.117,
"0.80",.181875,.126,
"0.85",.1965625,.134,
"0.90",.211875,.142,
"0.95",.229375,.151,
"1.00",.2471875,.159,
"1.05",.265,.167,
"1.10",.2853125,.176,
"1.15",.3059375,.184,
"1.20",.3246875,.192,
"1.25",.343125,.201,
"1.30",.363125,.209,
"1.35",.3821875,.217,
"1.40",.4015625,.226,
"1.45",.42,.234,
"1.50",.4371875,.243,
"1.55",.453125,.251,
"1.60",.4675,.259,
"1.65",.4809375,.267,
"1.70",.4928125,.276,
"1.75",.5040625,.284,
"1.80",.5159375,.292,
"1.85",.526875,.301,
"1.90",.5384375,.309,
"1.95",.548125,.317,
"2.00",.559375,.326,
"2.05",.568125,.334,
"2.10",.5775,.343,
"2.15",.586875,.351,
"2.20",.5965625,.359,
"2.25",.6059375,.367,
"2.30",.615,.376,
"2.35",.6253125,.384,
"2.40",.6340625,.392,
"2.45",.645,.401,
"2.50",.6553125,.409,
"2.55",.665,.417,
"2.60",.6753125,.426,
"2.65",.6871875,.434,
"2.70",.6971875,.442,
"2.75",.708125,.451,
"2.80",.7209375,.459,
"2.85",.7309375,.467,
"2.90",.7421875,.476,
"2.95",.754375,.484,
"3.00",.765,.492,
"3.05",.77625,.501,
"3.10",.7875,.509,
"3.15",.800625,.517,
"3.20",.8115625,.526,
"3.25",.8240625,.534,
"3.30",.8359375,.543,
"3.35",.8475,.551,
"3.40",.8603125,.559,
"3.45",.873125,.567,
"3.50",.8859375,.576,
"3.55",.8978125,.584,
"3.60",.9103125,.592,
"3.65",.923125,.601,
"3.70",.9359375,.609,
"3.75",.948125,.617,
"3.80",.9609375,.626,
"3.85",.975,.634,
"3.90",.9875,.642,
"3.95",1.000937,.651,
"4.00",1.014375,.659,
"4.05",1.027187,.667,
"4.10",1.039688,.676,
"4.15",1.053125,.684,
"4.20",1.065938,.692,
"4.25",1.079062,.701,
"4.30",1.092188,.709,
"4.35",1.105,.717,
"4.40",1.118125,.726,
"4.45",1.1325,.734,
"4.50",1.145313,.743,
"4.55",1.158125,.751,
"4.60",1.171875,.759,
"4.65",1.185938,.767,
"4.70",1.199687,.776,
"4.75",1.212813,.784,
"4.80",1.22625,.792,
"4.85",1.239375,.801,
"4.90",1.252813,.809,
"4.95",1.265937,.817,
"5.00",1.278125,.826,
"5.05",1.292187,.834,
"5.10",1.305313,.843,
"5.15",1.318437,.851,
"5.20",1.33125,.859,
"5.25",1.343125,.868,
"5.30",1.355937,.876,
"5.35",1.37,.884,
"5.40",1.383125,.892,
"5.45",1.398125,.901,
"5.50",1.412187,.909,
"5.55",1.427187,.917,
"5.60",1.44125,.926,
"5.65",1.454687,.934,
"5.70",1.469687,.942,
"5.75",1.481875,.951,
"5.80",1.497187,.959,
"5.85",1.510937,.967,
"5.90",1.524063,.976,
"5.95",1.537812,.984,
"6.00",1.551875,.992,
"6.05",1.565625,1.001,
"6.10",1.580312,1.009,
"6.15",1.594375,1.017,
"6.20",1.6075,1.026,
"6.25",1.621875,1.034,
"6.30",1.635,1.043,
"6.35",1.650938,1.051,
"6.40",1.661562,1.059,
"6.45",1.67625,1.067,
"6.50",1.689375,1.076,
"6.55",1.703125,1.084,
"6.60",1.715937,1.092,
"6.65",1.72875,1.101,
"6.70",1.741562,1.109,
"6.75",1.754063,1.118,
"6.80",1.76625,1.126,
"6.85",1.779688,1.134,
"6.90",1.790938,1.142,
"6.95",1.803437,1.151,
"7.00",1.815625,1.159,
"7.05",1.8275,1.167,
"7.10",1.84,1.176,
"7.15",1.85125,1.184,
"7.20",1.86375,1.192,
"7.25",1.875625,1.201,
"7.30",1.885625,1.209,
"7.35",1.896562,1.218,
"7.40",1.906875,1.226,
"7.45",1.917187,1.234,
"7.50",1.926875,1.243,
"7.55",1.9375,1.251,
"7.60",1.947188,1.259,
"7.65",1.956563,1.267,
"7.70",1.967188,1.276,
"7.75",1.97625,1.284,
"7.80",1.985937,1.292,
"7.85",1.995937,1.301,
"7.90",2.005625,1.309,
"7.95",2.015312,1.317,
"8.00",2.024688,1.326,
"8.05",2.034062,1.334,
"8.10",2.043437,1.343,
"8.15",2.05375,1.351,
"8.20",2.063437,1.359,
"8.25",2.073125,1.367,
"8.30",2.082813,1.376,
"8.35",2.093125,1.384,
"8.40",2.102187,1.392,
"8.45",2.112187,1.401,
"8.50",2.121562,1.409,
"8.55",2.132813,1.417,
"8.60",2.141562,1.426,
"8.65",2.153438,1.434,
"8.70",2.161562,1.442,
"8.75",2.170625,1.451,
"8.80",2.181875,1.459,
"8.85",2.192188,1.467,
"8.90",2.20125,1.476,
"8.95",2.21125,1.484,
"9.00",2.221562,1.492,
"9.05",2.230937,1.501,
"9.10",2.24125,1.509,
"9.15",2.250625,1.517,
"9.20",2.26,1.526,
"9.25",2.27,1.534,
"9.30",2.27875,1.543,
"9.35",2.287812,1.551,
"9.40",2.29625,1.559,
"9.45",2.30375,1.567,
"9.50",2.310625,1.576,
"9.55",2.31875,1.584,
"9.60",2.326562,1.592,
"9.65",2.336562,1.601,
"9.70",2.345,1.609,
"9.75",2.355625,1.618,
"9.80",2.364063,1.626,
"9.85",2.374375,1.634,
"9.90",2.385,1.642,
"9.95",2.394375,1.651,
"10.00",2.404687,1.659,
"10.05",2.415,1.668,
"10.10",2.425313,1.676,
"10.15",2.435313,1.684,
"10.20",2.445625,1.692,
"10.25",2.455937,1.701,
"10.30",2.466563,1.709,
"10.35",2.476563,1.718,
"10.40",2.4875,1.726,
"10.45",2.497188,1.734,
"10.50",2.5075,1.743,
"10.55",2.517812,1.751,
"10.60",2.5275,1.759,
"10.65",2.5375,1.767,
"10.70",2.548438,1.776,
"10.75",2.558438,1.784,
"10.80",2.569375,1.792,
"10.85",2.579375,1.801,
"10.90",2.590312,1.809,
"10.95",2.599375,1.817,
"11.00",2.609375,1.826,
"11.05",2.620938,1.834,
"11.10",2.630312,1.842,
"11.15",2.640938,1.851,
"11.20",2.650625,1.859,
"11.25",2.660625,1.867,
"11.30",2.670938,1.876,
"11.35",2.680625,1.884,
"11.40",2.690625,1.892,
"11.45",2.700625,1.901,
"11.50",2.710625,1.909,
"11.55",2.720937,1.917,
"11.60",2.73125,1.926,
"11.65",2.740937,1.934,
"11.70",2.752187,1.942,
"11.75",2.761875,1.951,
"11.80",2.773125,1.959,
"11.85",2.784375,1.967,
"11.90",2.794375,1.976,
"11.95",2.805,1.984,
"12.00",2.814687,1.992,
"12.05",2.825938,2.001,
"12.10",2.835625,2.009,
"12.15",2.845937,2.017,
"12.20",2.85625,2.026,
"12.25",2.865937,2.034,
"12.30",2.876563,2.043,
"12.35",2.886563,2.051,
"12.40",2.896563,2.059,
"12.45",2.906875,2.067,
"12.50",2.917187,2.076,
"12.55",2.927187,2.084,
"12.60",2.937187,2.092,
"12.65",2.947187,2.101,
"12.70",2.956563,2.109,
"12.75",2.967813,2.118,
"12.80",2.978125,2.126,
"12.85",2.9875,2.134,
"12.90",2.998437,2.142,
"12.95",3.009063,2.151,
"13.00",3.019063,2.159,
"13.05",3.029687,2.168,
"13.10",3.040625,2.176,
"13.15",3.050937,2.184,
"13.20",3.06125,2.192,
"13.25",3.071563,2.201,
"13.30",3.081875,2.209,
"13.35",3.092187,2.217,
"13.40",3.102187,2.226,
"13.45",3.113437,2.234,
"13.50",3.124375,2.243,
"13.55",3.135,2.251,
"13.60",3.145313,2.259,
"13.65",3.155625,2.267,
"13.70",3.16625,2.276,
"13.75",3.176563,2.284,
"13.80",3.1875,2.292,
"13.85",3.198437,2.301,
"13.90",3.209063,2.309,
"13.95",3.219687,2.317,
"14.00",3.230625,2.326,
"14.05",3.240625,2.334,
"14.10",3.251563,2.343,
"14.15",3.262187,2.351,
"14.20",3.273438,2.359,
"14.25",3.283437,2.368,
"14.30",3.295312,2.376,
"14.35",3.305,2.384,
"14.40",3.315312,2.392,
"14.45",3.326875,2.401,
"14.50",3.3375,2.409,
"14.55",3.348125,2.417,
"14.60",3.359062,2.426,
"14.65",3.369375,2.434,
"14.70",3.380625,2.442,
"14.75",3.39125,2.451,
"14.80",3.401875,2.459,
"14.85",3.413438,2.467,
"14.90",3.424375,2.476,
"14.95",3.435625,2.484,
"15.00",3.446875,2.492,
"15.05",3.457187,2.501,
"15.10",3.47,2.509,
"15.15",3.480625,2.517,
"15.20",3.491563,2.526,
"15.25",3.504688,2.534,
"15.30",3.515,2.543,
"15.35",3.52625,2.551,
"15.40",3.537188,2.559,
"15.45",3.548125,2.567,
"15.50",3.55875,2.576,
"15.55",3.570313,2.584,
"15.60",3.581875,2.592,
"15.65",3.592187,2.601,
"15.70",3.604687,2.609,
"15.75",3.61625,2.617,
"15.80",3.6275,2.626,
"15.85",3.639062,2.634,
"15.90",3.650625,2.642,
"15.95",3.661875,2.651,
"16.00",3.673438,2.659,
"16.05",3.685625,2.668,
"16.10",3.695937,2.676,
"16.15",3.708125,2.684,
"16.20",3.71875,2.692,
"16.25",3.730313,2.701,
"16.30",3.741875,2.709,
"16.35",3.753438,2.717,
"16.40",3.765,2.726,
"16.45",3.776562,2.734,
"16.50",3.7875,2.743,
"16.55",3.799375,2.751,
"16.60",3.810937,2.759,
"16.65",3.821563,2.767,
"16.70",3.833437,2.776,
"16.75",3.845625,2.784,
"16.80",3.857188,2.792,
"16.85",3.868438,2.801,
"16.90",3.880312,2.809,
"16.95",3.891562,2.817,
"17.00",3.904063,2.826,
"17.05",3.915937,2.834,
"17.10",3.926563,2.843,
"17.15",3.939375,2.851,
"17.20",3.95125,2.859,
"17.25",3.9625,2.867,
"17.30",3.974688,2.876,
"17.35",3.985938,2.884,
"17.40",3.9975,2.892,
"17.45",4.008438,2.901,
"17.50",4.020312,2.909,
"17.55",4.033125,2.917,
"17.60",4.043437,2.926,
"17.65",4.056562,2.934,
"17.70",4.066875,2.942,
"17.75",4.07875,2.951,
"17.80",4.090625,2.959,
"17.85",4.1025,2.967,
"17.90",4.115313,2.976,
"17.95",4.126563,2.984,
"18.00",4.140937,2.992,
"18.05",4.15125,3.001,
"18.10",4.165312,3.009,
"18.15",4.177813,3.017,
"18.20",4.190312,3.026,
"18.25",4.203125,3.034,
"18.30",4.215312,3.042,
"18.35",4.229063,3.051,
"18.40",4.240938,3.059,
"18.45",4.253438,3.067,
"18.50",4.265937,3.076,
"18.55",4.279062,3.084,
"18.60",4.292188,3.092,
"18.65",4.30375,3.101,
"18.70",4.317187,3.109,
"18.75",4.33,3.117,
"18.80",4.343438,3.126,
"18.85",4.356563,3.134,
"18.90",4.369688,3.142,
"18.95",4.3825,3.151,
"19.00",4.39625,3.159,
"19.05",4.410313,3.168,
"19.10",4.4225,3.176,
"19.15",4.435,3.184,
"19.20",4.449375,3.192,
"19.25",4.460625,3.201,
"19.30",4.474688,3.209,
"19.35",4.488125,3.217,
"19.40",4.499688,3.226,
"19.45",4.514688,3.234,
"19.50",4.528125,3.243,
"19.55",4.540937,3.251,
"19.60",4.554062,3.259,
"19.65",4.5675,3.267,
"19.70",4.580313,3.276,
"19.75",4.594375,3.284,
"19.80",4.608125,3.292,
"19.85",4.620937,3.301,
"19.90",4.634375,3.309,
"19.95",4.648125,3.317,
"20.00",4.661562,3.326,
"20.05",4.674375,3.334,
"20.10",4.688125,3.342,
"20.15",4.700937,3.351,
"20.20",4.715,3.359,
"20.25",4.727812,3.368,
"20.30",4.741562,3.376,
"20.35",4.755625,3.384,
"20.40",4.768437,3.392,
"20.45",4.78125,3.401,
"20.50",4.795312,3.409,
"20.55",4.809688,3.417,
"20.60",4.822813,3.426,
"20.65",4.836875,3.434,
"20.70",4.850313,3.442,
"20.75",4.864375,3.451,
"20.80",4.879063,3.459,
"20.85",4.892188,3.467,
"20.90",4.905938,3.476,
"20.95",4.920312,3.484,
"21.00",4.934688,3.492,
"21.05",4.9475,3.501,
"21.10",4.962812,3.509,
"21.15",4.975625,3.517,
"21.20",4.990625,3.526,
"21.25",5.004375,3.534,
"21.30",5.019063,3.543,
"21.35",5.032813,3.551,
"21.40",5.045938,3.559,
"21.45",5.059688,3.567,
"21.50",5.07375,3.576,
"21.55",5.087187,3.584,
"21.60",5.100937,3.592,
"21.65",5.114687,3.601,
"21.70",5.129375,3.609,
"21.75",5.143125,3.617,
"21.80",5.155938,3.626,
"21.85",5.171563,3.634,
"21.90",5.185625,3.642,
"21.95",5.200625,3.651,
"22.00",5.214687,3.659,
"22.05",5.228437,3.667,
"22.10",5.244062,3.676,
"22.15",5.25625,3.684,
"22.20",5.27125,3.692,
"22.25",5.285313,3.701,
"22.30",5.299375,3.709,
"22.35",5.314063,3.717,
"22.40",5.328125,3.726,
"22.45",5.341562,3.734,
"22.50",5.356875,3.743,
"22.55",5.370625,3.751,
"22.60",5.384687,3.759,
"22.65",5.398438,3.767,
"22.70",5.413437,3.776,
"22.75",5.428125,3.784,
"22.80",5.4425,3.792,
"22.85",5.456875,3.801,
"22.90",5.4725,3.809,
"22.95",5.485312,3.817,
"23.00",5.50125,3.826,
"23.05",5.514688,3.834,
"23.10",5.528125,3.842,
"23.15",5.5425,3.851,
"23.20",5.556875,3.859,
"23.25",5.571562,3.868,
"23.30",5.585625,3.876,
"23.35",5.599375,3.884,
"23.40",5.615,3.892,
"23.45",5.628438,3.901,
"23.50",5.6425,3.909,
"23.55",5.656562,3.917,
"23.60",5.670625,3.926,
"23.65",5.685312,3.934,
"23.70",5.699062,3.942,
"23.75",5.71375,3.951,
"23.80",5.729063,3.959,
"23.85",5.7425,3.967,
"23.90",5.757813,3.976,
"23.95",5.771875,3.984,
"24.00",5.7875,3.992,
"24.05",5.800938,4.001,
"24.10",5.815625,4.009,
"24.15",5.831563,4.017,
"24.20",5.845,4.026,
"24.25",5.860312,4.034,
"24.30",5.875,4.042,
"24.35",5.889375,4.051,
"24.40",5.903438,4.059,
"24.45",5.918437,4.067,
"24.50",5.931875,4.076,
"24.55",5.946562,4.084,
"24.60",5.96,4.092,
"24.65",5.974688,4.101,
"24.70",5.98875,4.109,
"24.75",6.00375,4.117,
"24.80",6.018125,4.126,
"24.85",6.033438,4.134,
"24.90",6.04875,4.142,
"24.95",6.0625,4.151,
"25.00",6.076562,4.159,
"25.05",6.093125,4.168,
"25.10",6.106563,4.176,
"25.15",6.122812,4.184,
"25.20",6.136562,4.192,
"25.25",6.150938,4.201,
"25.30",6.166875,4.209,
"25.35",6.18125,4.217,
"25.40",6.196875,4.226,
"25.45",6.2125,4.234,
"25.50",6.227188,4.243,
"25.55",6.243125,4.251,
"25.60",6.258125,4.259,
"25.65",6.272812,4.267,
"25.70",6.288125,4.276,
"25.75",6.304062,4.284,
"25.80",6.318438,4.292,
"25.85",6.333125,4.301,
"25.90",6.348437,4.309,
"25.95",6.363438,4.317,
"26.00",6.378125,4.326,
"26.05",6.394375,4.334,
"26.10",6.408125,4.342,
"26.15",6.423438,4.351,
"26.20",6.439375,4.359,
"26.25",6.454375,4.368,
"26.30",6.469375,4.376,
"26.35",6.485938,4.384,
"26.40",6.5,4.392,
"26.45",6.515313,4.401,
"26.50",6.53,4.409,
"26.55",6.545938,4.417,
"26.60",6.559688,4.426,
"26.65",6.574687,4.434,
"26.70",6.589375,4.442,
"26.75",6.605,4.451,
"26.80",6.619375,4.459,
"26.85",6.635313,4.467,
"26.90",6.650312,4.476,
"26.95",6.665312,4.484,
"27.00",6.680937,4.492,
"27.05",6.695313,4.501,
"27.10",6.711875,4.509,
"27.15",6.727812,4.517,
"27.20",6.741875,4.526,
"27.25",6.757187,4.534,
"27.30",6.771563,4.542,
"27.35",6.787188,4.551,
"27.40",6.8,4.559,
"27.40",6.8,4.559,
"27.40",6.8,4.559,