File: EC4/GF5.csv
"Test Name","Test Mode","Test Type","Control","Test Speed 1","Test Speed 2","Test Speed 3","Change Point 1","Change Point 2","Disp. Origin","Break and Limit Action","Sensitivity:","Level:"
"","Single","Tensile","Stroke",10,1,1,"Off","Off","Start","Stop",50,5

"Title","Sub title","Comment"
"","",""

"Shape:","Batch Size:","SubBatch Size:"
"Plate",1,1
"Name:","Thickness","Width","Gauge Length",
"Size Unit:","mm","mm","mm",
" Glass Fiber","1.1800","10.5800","60.0000",

"Name","Max_Force",
"Parameter",,
"Units","kN",
" Glass Fiber","2.07938",

" 1- 1"
"Time","Force","Stroke",
"sec","kN","mm",
"0.00",.0003125,0,
"0.05",.0003125,0,
"0.10",1.71875E-03,.006,
"0.15",.0078125,.013,
"0.20",.01875,.021,
"0.25",3.234375E-02,.03,
"0.30",.045625,.038,
"0.35",.0596875,.046,
"0.40",7.171875E-02,.055,
"0.45",.08375,.063,
"0.50",9.453125E-02,.071,
"0.55",.1051563,.08,
"0.60",.1160937,.088,
"0.65",.1267187,.096,
"0.70",.1371875,.105,
"0.75",.14625,.113,
"0.80",.1559375,.121,
"0.85",.1653125,.13,
"0.90",.1732813,.138,
"0.95",.1814062,.146,
"1.00",.18875,.155,
"1.05",.19625,.163,
"1.10",.2034375,.171,
"1.15",.2107812,.18,
"1.20",.2176563,.188,
"1.25",.2245312,.196,
"1.30",.2304688,.204,
"1.35",.23625,.213,
"1.40",.2425,.221,
"1.45",.2476563,.23,
"1.50",.2526563,.238,
"1.55",.2571875,.246,
"1.60",.2621875,.255,
"1.65",.266875,.263,
"1.70",.2720312,.271,
"1.75",.27625,.28,
"1.80",.2807812,.288,
"1.85",.2848437,.296,
"1.90",.2892188,.304,
"1.95",.293125,.313,
"2.00",.2975,.321,
"2.05",.3017187,.33,
"2.10",.3057812,.338,
"2.15",.31,.346,
"2.20",.31375,.355,
"2.25",.318125,.363,
"2.30",.3221875,.371,
"2.35",.3267187,.38,
"2.40",.3309375,.388,
"2.45",.3348438,.396,
"2.50",.3392187,.405,
"2.55",.3428125,.413,
"2.60",.3473437,.421,
"2.65",.35125,.43,
"2.70",.3553125,.438,
"2.75",.3596875,.446,
"2.80",.3635938,.455,
"2.85",.3676563,.463,
"2.90",.3725,.471,
"2.95",.3759375,.48,
"3.00",.3796875,.488,
"3.05",.384375,.496,
"3.10",.3879687,.505,
"3.15",.3914062,.513,
"3.20",.395625,.521,
"3.25",.3995312,.53,
"3.30",.4028125,.538,
"3.35",.4067188,.546,
"3.40",.4101563,.555,
"3.45",.4135937,.563,
"3.50",.4171875,.571,
"3.55",.4209375,.58,
"3.60",.4246875,.588,
"3.65",.4290625,.596,
"3.70",.4332812,.605,
"3.75",.4379688,.613,
"3.80",.4420313,.621,
"3.85",.4464062,.63,
"3.90",.4509375,.638,
"3.95",.4551562,.646,
"4.00",.4590625,.655,
"4.05",.4632812,.663,
"4.10",.4667188,.671,
"4.15",.4709375,.68,
"4.20",.4746875,.688,
"4.25",.4784375,.696,
"4.30",.4823438,.705,
"4.35",.4873438,.713,
"4.40",.4909375,.721,
"4.45",.4951563,.73,
"4.50",.49875,.738,
"4.55",.5029687,.746,
"4.60",.506875,.755,
"4.65",.51125,.763,
"4.70",.5151563,.771,
"4.75",.519375,.78,
"4.80",.5235937,.788,
"4.85",.5276563,.796,
"4.90",.53125,.805,
"4.95",.5354688,.813,
"5.00",.54,.821,
"5.05",.544375,.83,
"5.10",.5475,.838,
"5.15",.5510938,.846,
"5.20",.5551562,.855,
"5.25",.5596875,.863,
"5.30",.5645313,.871,
"5.35",.5684375,.88,
"5.40",.5728125,.888,
"5.45",.5778125,.896,
"5.50",.5820313,.905,
"5.55",.5865625,.913,
"5.60",.5909375,.921,
"5.65",.5954688,.93,
"5.70",.6001562,.938,
"5.75",.6046875,.946,
"5.80",.6089063,.955,
"5.85",.6140625,.963,
"5.90",.6179687,.971,
"5.95",.6228125,.98,
"6.00",.6273438,.988,
"6.05",.6315625,.996,
"6.10",.6360937,1.005,
"6.15",.640625,1.013,
"6.20",.6454688,1.021,
"6.25",.6503125,1.03,
"6.30",.6551563,1.038,
"6.35",.6595312,1.046,
"6.40",.6639063,1.055,
"6.45",.6689063,1.063,
"6.50",.673125,1.071,
"6.55",.6779687,1.08,
"6.60",.6826562,1.088,
"6.65",.6870313,1.096,
"6.70",.691875,1.105,
"6.75",.6964062,1.113,
"6.80",.7014062,1.121,
"6.85",.70625,1.13,
"6.90",.7107813,1.138,
"6.95",.7159375,1.146,
"7.00",.7210938,1.155,
"7.05",.7264063,1.163,
"7.10",.7314063,1.171,
"7.15",.7370312,1.18,
"7.20",.741875,1.188,
"7.25",.746875,1.196,
"7.30",.7514063,1.205,
"7.35",.7564062,1.213,
"7.40",.7614062,1.221,
"7.45",.7657812,1.23,
"7.50",.7703125,1.238,
"7.55",.775,1.246,
"7.60",.7795312,1.255,
"7.65",.7842187,1.263,
"7.70",.7890625,1.271,
"7.75",.7939063,1.28,
"7.80",.7982813,1.288,
"7.85",.8035938,1.296,
"7.90",.8079687,1.305,
"7.95",.8129687,1.313,
"8.00",.8173438,1.321,
"8.05",.8226563,1.33,
"8.10",.8276563,1.338,
"8.15",.8325,1.346,
"8.20",.8370312,1.355,
"8.25",.8417187,1.363,
"8.30",.8467187,1.371,
"8.35",.8514063,1.38,
"8.40",.85625,1.388,
"8.45",.8614063,1.396,
"8.50",.86625,1.405,
"8.55",.8709375,1.413,
"8.60",.875625,1.421,
"8.65",.8807812,1.43,
"8.70",.8853125,1.438,
"8.75",.8903125,1.446,
"8.80",.8945313,1.455,
"8.85",.8995312,1.463,
"8.90",.905,1.471,
"8.95",.9098437,1.48,
"9.00",.9146875,1.488,
"9.05",.919375,1.496,
"9.10",.9245312,1.505,
"9.15",.929375,1.513,
"9.20",.934375,1.521,
"9.25",.9398438,1.53,
"9.30",.9446875,1.538,
"9.35",.949375,1.546,
"9.40",.9546875,1.555,
"9.45",.96,1.563,
"9.50",.9653125,1.571,
"9.55",.97,1.58,
"9.60",.9753125,1.588,
"9.65",.9798437,1.596,
"9.70",.9853125,1.605,
"9.75",.9909375,1.613,
"9.80",.995625,1.621,
"9.85",1.000469,1.63,
"9.90",1.005781,1.638,
"9.95",1.01125,1.646,
"10.00",1.01625,1.655,
"10.05",1.021094,1.663,
"10.10",1.026406,1.671,
"10.15",1.031875,1.68,
"10.20",1.036562,1.688,
"10.25",1.042187,1.696,
"10.30",1.047187,1.705,
"10.35",1.052187,1.713,
"10.40",1.057188,1.721,
"10.45",1.062188,1.73,
"10.50",1.067344,1.738,
"10.55",1.0725,1.746,
"10.60",1.076875,1.755,
"10.65",1.082656,1.763,
"10.70",1.087813,1.771,
"10.75",1.093125,1.78,
"10.80",1.098281,1.788,
"10.85",1.103281,1.796,
"10.90",1.108594,1.805,
"10.95",1.112969,1.813,
"11.00",1.119531,1.821,
"11.05",1.124531,1.83,
"11.10",1.129531,1.838,
"11.15",1.134531,1.846,
"11.20",1.14,1.855,
"11.25",1.145313,1.863,
"11.30",1.150625,1.871,
"11.35",1.155938,1.88,
"11.40",1.161875,1.888,
"11.45",1.167031,1.896,
"11.50",1.1725,1.905,
"11.55",1.177969,1.913,
"11.60",1.183281,1.921,
"11.65",1.188594,1.93,
"11.70",1.193437,1.938,
"11.75",1.199219,1.946,
"11.80",1.203906,1.955,
"11.85",1.209062,1.963,
"11.90",1.214062,1.971,
"11.95",1.219375,1.98,
"12.00",1.224687,1.988,
"12.05",1.23,1.996,
"12.10",1.235312,2.005,
"12.15",1.240625,2.013,
"12.20",1.245937,2.021,
"12.25",1.251562,2.03,
"12.30",1.257187,2.038,
"12.35",1.262812,2.046,
"12.40",1.268281,2.055,
"12.45",1.273594,2.063,
"12.50",1.27875,2.071,
"12.55",1.284531,2.08,
"12.60",1.289688,2.088,
"12.65",1.295625,2.096,
"12.70",1.301094,2.105,
"12.75",1.30625,2.113,
"12.80",1.311719,2.121,
"12.85",1.3175,2.13,
"12.90",1.322969,2.138,
"12.95",1.329062,2.146,
"13.00",1.335,2.155,
"13.05",1.339844,2.163,
"13.10",1.345469,2.171,
"13.15",1.350937,2.18,
"13.20",1.356719,2.188,
"13.25",1.362188,2.196,
"13.30",1.367969,2.205,
"13.35",1.374375,2.213,
"13.40",1.379531,2.221,
"13.45",1.385313,2.23,
"13.50",1.390937,2.238,
"13.55",1.396406,2.246,
"13.60",1.402187,2.255,
"13.65",1.407812,2.263,
"13.70",1.414063,2.271,
"13.75",1.419375,2.28,
"13.80",1.425156,2.288,
"13.85",1.430938,2.296,
"13.90",1.43625,2.305,
"13.95",1.442188,2.313,
"14.00",1.447656,2.321,
"14.05",1.454219,2.33,
"14.10",1.459844,2.338,
"14.15",1.465312,2.346,
"14.20",1.47125,2.355,
"14.25",1.476563,2.363,
"14.30",1.482969,2.371,
"14.35",1.488125,2.38,
"14.40",1.494063,2.388,
"14.45",1.5,2.396,
"14.50",1.505469,2.405,
"14.55",1.510937,2.413,
"14.60",1.516719,2.421,
"14.65",1.522344,2.43,
"14.70",1.527812,2.438,
"14.75",1.53375,2.446,
"14.80",1.539375,2.455,
"14.85",1.544844,2.463,
"14.90",1.550625,2.471,
"14.95",1.556719,2.48,
"15.00",1.561875,2.488,
"15.05",1.567656,2.496,
"15.10",1.5725,2.505,
"15.15",1.579062,2.513,
"15.20",1.584375,2.521,
"15.25",1.590781,2.53,
"15.30",1.596563,2.538,
"15.35",1.602344,2.546,
"15.40",1.607969,2.555,
"15.45",1.61375,2.563,
"15.50",1.619375,2.571,
"15.55",1.625469,2.58,
"15.60",1.630625,2.588,
"15.65",1.636406,2.596,
"15.70",1.642344,2.605,
"15.75",1.648438,2.613,
"15.80",1.65375,2.621,
"15.85",1.659531,2.63,
"15.90",1.665,2.638,
"15.95",1.670469,2.646,
"16.00",1.67625,2.655,
"16.05",1.682031,2.663,
"16.10",1.687656,2.671,
"16.15",1.693125,2.68,
"16.20",1.699219,2.688,
"16.25",1.705156,2.696,
"16.30",1.710938,2.705,
"16.35",1.716875,2.713,
"16.40",1.722656,2.721,
"16.45",1.728594,2.73,
"16.50",1.734219,2.738,
"16.55",1.739687,2.746,
"16.60",1.745469,2.755,
"16.65",1.751094,2.763,
"16.70",1.757187,2.771,
"16.75",1.762187,2.78,
"16.80",1.769063,2.788,
"16.85",1.774219,2.796,
"16.90",1.779688,2.805,
"16.95",1.785625,2.813,
"17.00",1.791719,2.821,
"17.05",1.7975,2.83,
"17.10",1.803594,2.838,
"17.15",1.808906,2.846,
"17.20",1.814687,2.855,
"17.25",1.82,2.863,
"17.30",1.825938,2.871,
"17.35",1.831563,2.88,
"17.40",1.837656,2.888,
"17.45",1.84375,2.896,
"17.50",1.849687,2.905,
"17.55",1.855781,2.913,
"17.60",1.862031,2.921,
"17.65",1.866719,2.93,
"17.70",1.872969,2.938,
"17.75",1.878594,2.946,
"17.80",1.884688,2.955,
"17.85",1.890625,2.963,
"17.90",1.897344,2.971,
"17.95",1.902656,2.98,
"18.00",1.907656,2.988,
"18.05",1.914219,2.996,
"18.10",1.920156,3.005,
"18.15",1.92625,3.013,
"18.20",1.932344,3.021,
"18.25",1.938281,3.03,
"18.30",1.944531,3.038,
"18.35",1.950469,3.046,
"18.40",1.956094,3.055,
"18.45",1.962188,3.063,
"18.50",1.968438,3.071,
"18.55",1.97375,3.08,
"18.60",1.980781,3.088,
"18.65",1.985937,3.096,
"18.70",1.991719,3.105,
"18.75",1.996562,3.113,
"18.80",2.003125,3.121,
"18.85",2.008125,3.13,
"18.90",2.013906,3.138,
"18.95",2.019219,3.146,
"19.00",2.025,3.155,
"19.05",2.030313,3.163,
"19.10",2.036094,3.171,
"19.15",2.042031,3.18,
"19.20",2.047344,3.188,
"19.25",2.052813,3.196,
"19.30",2.058906,3.205,
"19.35",2.064219,3.213,
"19.40",2.069375,3.221,
"19.45",2.074531,3.23,
"19.50",2.07875,3.238,
"19.55",2.079375,3.246,
"19.55",2.079375,3.246,
"19.55",2.079375,3.246,